Workbook

Sheet Raw_Data
A1: 1 | B1: gender | C1: bdate | D1: educ | E1: jobcat | F1: salary | G1: salbegin | H1: jobtime | I1: prevexp | J1: minority
A2: 1.0 | B2: Male | C2: 1952-02-03 | D2: 15 | E2: Manager | F2: 57000.0 | G2: 27000.0 | H2: 98.0 | I2: 144.0 | J2: No
A3: 2.0 | B3: Male | C3: 1958-05-23 | D3: 16 | E3: Clerical | F3: 40200.0 | G3: 18750.0 | H3: 98.0 | I3: 36.0 | J3: No
A4: 3.0 | B4: Female | C4: 1929-07-26 | D4: 12 | E4: Clerical | F4: 21450.0 | G4: 12000.0 | H4: 98.0 | I4: 381.0 | J4: No
A5: 4.0 | B5: Female | C5: 1947-04-15 | D5: 8 | E5: Clerical | F5: 21900.0 | G5: 13200.0 | H5: 98.0 | I5: 190.0 | J5: No
A6: 5.0 | B6: Male | C6: 1955-02-09 | D6: 15 | E6: Clerical | F6: 45000.0 | G6: 21000.0 | H6: 98.0 | I6: 138.0 | J6: No
A7: 6.0 | B7: Male | C7: 1958-08-22 | D7: 15 | E7: Clerical | F7: 32100.0 | G7: 13500.0 | H7: 98.0 | I7: 67.0 | J7: No
A8: 7.0 | B8: Male | C8: 1956-04-26 | D8: 15 | E8: Clerical | F8: 36000.0 | G8: 18750.0 | H8: 98.0 | I8: 114.0 | J8: No
A9: 8.0 | B9: Female | C9: 1966-05-06 | D9: 12 | E9: Clerical | F9: 21900.0 | G9: 9750.0 | H9: 98.0 | I9: missing | J9: No
A10: 9.0 | B10: Female | C10: 1946-01-23 | D10: 15 | E10: Clerical | F10: 27900.0 | G10: 12750.0 | H10: 98.0 | I10: 115.0 | J10: No
A11: 10.0 | B11: Female | C11: 1946-02-13 | D11: 12 | E11: Clerical | F11: 24000.0 | G11: 13500.0 | H11: 98.0 | I11: 244.0 | J11: No
A12: 11.0 | B12: Female | C12: 1950-02-07 | D12: 16 | E12: Clerical | F12: 30300.0 | G12: 16500.0 | H12: 98.0 | I12: 143.0 | J12: No
A13: 12.0 | B13: Male | C13: 1966-01-11 | D13: 8 | E13: Clerical | F13: 28350.0 | G13: 12000.0 | H13: 98.0 | I13: 26.0 | J13: Yes
... A434: 433.0 | B434: Male | C434: 1966-11-15 | D434: 12 | E434: Clerical | F434: 33540.0 | G434: 15750.0 | H434: 66.0 | I434: 47.0 | J434: No
A435: 434.0 | B435: Male | D435: 16 | E435: Clerical | F435: 34950.0 | G435: 20250.0 | H435: 66.0 | I435: 55.0 | J435: No
A436: 435.0 | B436: Male | C436: 1964-05-24 | D436: 15 | E436: Clerical | F436: 40350.0 | G436: 16500.0 | H436: 66.0 | I436: 80.0 | J436: No
A437: 436.0 | B437: Male | C437: 1965-05-27 | D437: 12 | E437: Clerical | F437: 30270.0 | G437: 15750.0 | H437: 66.0 | I437: 80.0 | J437: No
A438: 437.0 | B438: Male | C438: 1933-09-04 | D438: 8 | E438: Clerical | F438: 26250.0 | G438: 16050.0 | H438: 66.0 | I438: 264.0 | J438: No
A439: 438.0 | B439: Male | C439: 1964-10-11 | D439: 15 | E439: Clerical | F439: 32400.0 | G439: 15000.0 | H439: 66.0 | I439: 64.0 | J439: No
A440: 439.0 | B440: Female | C440: 1970-06-25 | D440: 12 | E440: Clerical | F440: 20400.0 | G440: 11250.0 | H440: 66.0 | I440: missing | J440: No
A441: 440.0 | B441: Female | C441: 1947-11-10 | D441: 8 | E441: Clerical | F441: 24150.0 | G441: 12750.0 | H441: 66.0 | I441: 96.0 | J441: No
A442: 441.0 | B442: Female | C442: 1949-08-02 | D442: 15 | E442: Clerical | F442: 23850.0 | G442: 13500.0 | H442: 66.0 | I442: 122.0 | J442: No
A443: 442.0 | B443: Female | C443: 1968-09-18 | D443: 12 | E443: Clerical | F443: 29700.0 | G443: 13500.0 | H443: 66.0 | I443: 26.0 | J443: No
A444: 443.0 | B444: Female | C444: 1929-02-10 | D444: 8 | E444: Clerical | F444: 21600.0 | G444: 13500.0 | H444: 66.0 | I444: 228.0 | J444: No
A445: 444.0 | B445: Female | C445: 1961-09-16 | D445: 12 | E445: Clerical | F445: 24450.0 | G445: 15750.0 | H445: 66.0 | I445: 87.0 | J445: No
A446: 445.0 | B446: Male | C446: 1963-08-04 | D446: 15 | E446: Clerical | F446: 28050.0 | G446: 16500.0 | H446: 66.0 | I446: 84.0 | J446: Yes
A447: 446.0 | B447: Male | C447: 1958-08-03 | D447: 16 | E447: Manager | F447: 100000.0 | G447: 44100.0 | H447: 66.0 | I447: 128.0 | J447: Yes
... A475: 474.0 | B475: Female | C475: 1968-11-05 | D475: 12 | E475: Clerical | F475: 29400.0 | G475: 14250.0 | H475: 63.0 | I475: 9.0 | J475: No

Sheet Cleaning_Log
A1: Cleaning Log and Assumptions
A3: Step | B3: What was found / done
A4: Rows imported | B4: 474 rows, 10 columns. Raw_Data sheet is an untouched copy.
A5: Remove duplicates | B5: 0 exact duplicate rows and 0 duplicate IDs found. Nothing removed. Rows after: 474.
A6: Blank values | B6: Birth Date blank for ID 434 (highlighted yellow). Left blank: a made-up date would be wrong and birth date is not used in any statistic.
A7: 'missing' text in Prev. Experience | B7: 24 cells contained the text 'missing'. Converted to true blanks (not 0) so averages are not dragged down. AVERAGE/MEDIAN ignore blanks; Summary shows the blank count.
A8: Column types | B8: Salary columns = Currency; Birth Date = Short Date (m/d/yyyy); numeric columns = Number; ID = whole number.
A9: TRIM text columns | B9: Checked every text cell for leading/trailing spaces: 0 found. In Excel you would use =TRIM(cell); nothing needed fixing here.
A10: Column mapping | B10: instructions mention Department, EmpID, DateofHire, DOB, Absences. This file has: Job Category (=Department), ID (=EmpID), Birth Date (=DOB). It has no hire date or absences column.
A11: Outlier to review | B11: ID 218: Clerical, starting salary $15,750, current salary $80,000. Looks like a possible data-entry error. Kept as-is; check the source before drawing conclusions about Clerical pay.
A12: Pivot tables | B12: Built as COUNTIF/AVERAGEIF tables so they stay live. Native PivotTable steps are in the Pivots sheet header.

Sheet Clean_Data
A1: ID | B1: Gender | C1: Birth Date | D1: Education (yrs) | E1: Job Category | F1: Current Salary | G1: Starting Salary | H1: Months in Job | I1: Prev. Experience (months) | J1: Minority
A2: 1 | B2: Male | C2: 19027 | D2: 15 | E2: Manager | F2: 57000 | G2: 27000 | H2: 98 | I2: 144 | J2: No
A3: 2 | B3: Male | C3: 21328 | D3: 16 | E3: Clerical | F3: 40200 | G3: 18750 | H3: 98 | I3: 36 | J3: No
A4: 3 | B4: Female | C4: 10800 | D4: 12 | E4: Clerical | F4: 21450 | G4: 12000 | H4: 98 | I4: 381 | J4: No
A5: 4 | B5: Female | C5: 17272 | D5: 8 | E5: Clerical | F5: 21900 | G5: 13200 | H5: 98 | I5: 190 | J5: No
A6: 5 | B6: Male | C6: 20129 | D6: 15 | E6: Clerical | F6: 45000 | G6: 21000 | H6: 98 | I6: 138 | J6: No
A7: 6 | B7: Male | C7: 21419 | D7: 15 | E7: Clerical | F7: 32100 | G7: 13500 | H7: 98 | I7: 67 | J7: No
A8: 7 | B8: Male | C8: 20571 | D8: 15 | E8: Clerical | F8: 36000 | G8: 18750 | H8: 98 | I8: 114 | J8: No
A9: 8 | B9: Female | C9: 24233 | D9: 12 | E9: Clerical | F9: 21900 | G9: 9750 | H9: 98 | J9: No
A10: 9 | B10: Female | C10: 16825 | D10: 15 | E10: Clerical | F10: 27900 | G10: 12750 | H10: 98 | I10: 115 | J10: No
A11: 10 | B11: Female | C11: 16846 | D11: 12 | E11: Clerical | F11: 24000 | G11: 13500 | H11: 98 | I11: 244 | J11: No
A12: 11 | B12: Female | C12: 18301 | D12: 16 | E12: Clerical | F12: 30300 | G12: 16500 | H12: 98 | I12: 143 | J12: No
A13: 12 | B13: Male | C13: 24118 | D13: 8 | E13: Clerical | F13: 28350 | G13: 12000 | H13: 98 | I13: 26 | J13: Yes
A14: 13 | B14: Male | C14: 22114 | D14: 15 | E14: Clerical | F14: 27750 | G14: 14250 | H14: 98 | I14: 34 | J14: Yes
A15: 14 | B15: Female | C15: 17955 | D15: 15 | E15: Clerical | F15: 35100 | G15: 16800 | H15: 98 | I15: 137 | J15: Yes
A16: 15 | B16: Male | C16: 22887 | D16: 12 | E16: Clerical | F16: 27300 | G16: 13500 | H16: 97 | I16: 66 | J16: No
A17: 16 | B17: Male | C17: 23698 | D17: 12 | E17: Clerical | F17: 40800 | G17: 15000 | H17: 97 | I17: 24 | J17: No
A18: 17 | B18: Male | C18: 22845 | D18: 15 | E18: Clerical | F18: 46000 | G18: 14250 | H18: 97 | I18: 48 | J18: No
A19: 18 | B19: Male | C19: 20534 | D19: 16 | E19: Manager | F19: 103750 | G19: 27510 | H19: 97 | I19: 70 | J19: No
A20: 19 | B20: Male | C20: 22877 | D20: 12 | E20: Clerical | F20: 42300 | G20: 14250 | H20: 97 | I20: 103 | J20: No
A21: 20 | B21: Female | C21: 14633 | D21: 12 | E21: Clerical | F21: 26250 | G21: 11550 | H21: 97 | I21: 48 | J21: No
... A73: 72 | B73: Female | C73: 23383 | D73: 16 | E73: Clerical | F73: 54000 | G73: 18000 | H73: 93 | I73: 11 | J73: No
A74: 73 | B74: Female | C74: 24877 | D74: 12 | E74: Clerical | F74: 26400 | G74: 10500 | H74: 93 | J74: No
A75: 74 | B75: Female | C75: 12172 | D75: 15 | E75: Clerical | F75: 33900 | G75: 19500 | H75: 93 | I75: 192 | J75: No
A76: 75 | B76: Female | C76: 23966 | D76: 15 | E76: Clerical | F76: 24150 | G76: 11550 | H76: 93 | J76: No
A77: 76 | B77: Female | C77: 24718 | D77: 15 | E77: Clerical | F77: 29250 | G77: 11550 | H77: 93 | I77: 11 | J77: No
A78: 77 | B78: Female | C78: 25090 | D78: 12 | E78: Clerical | F78: 27600 | G78: 11400 | H78: 93 | I78: 6 | J78: No
A79: 78 | B79: Female | C79: 25070 | D79: 12 | E79: Clerical | F79: 22950 | G79: 10500 | H79: 93 | I79: 10 | J79: No
A80: 79 | B80: Female | C80: 22669 | D80: 16 | E80: Clerical | F80: 34800 | G80: 14550 | H80: 93 | I80: 8 | J80: No
A81: 80 | B81: Female | C81: 22426 | D81: 16 | E81: Clerical | F81: 51000 | G81: 18000 | H81: 93 | I81: 22 | J81: No
A82: 81 | B82: Female | C82: 24909 | D82: 12 | E82: Clerical | F82: 24300 | G82: 10950 | H82: 93 | I82: 5 | J82: No
A83: 82 | B83: Female | C83: 17407 | D83: 12 | E83: Clerical | F83: 24750 | G83: 14250 | H83: 93 | I83: 193 | J83: Yes
A84: 83 | B84: Female | C84: 24757 | D84: 12 | E84: Clerical | F84: 22950 | G84: 11250 | H84: 93 | J84: Yes
A85: 84 | B85: Female | C85: 24543 | D85: 8 | E85: Clerical | F85: 25050 | G85: 10950 | H85: 93 | I85: 8 | J85: Yes
A86: 85 | B86: Male | C86: 22745 | D86: 15 | E86: Clerical | F86: 25950 | G86: 17100 | H86: 92 | I86: 42 | J86: No
A87: 86 | B87: Male | C87: 22518 | D87: 15 | E87: Clerical | F87: 31650 | G87: 15750 | H87: 92 | I87: 64 | J87: No
A88: 87 | B88: Male | C88: 21843 | D88: 12 | E88: Clerical | F88: 24150 | G88: 14100 | H88: 92 | I88: 130 | J88: No
A89: 88 | B89: Male | C89: 22687 | D89: 19 | E89: Manager | F89: 72500 | G89: 28740 | H89: 92 | I89: 10 | J89: No
A90: 89 | B90: Male | C90: 22456 | D90: 19 | E90: Manager | F90: 68750 | G90: 27480 | H90: 92 | I90: 8 | J90: No
A91: 90 | B91: Female | C91: 13938 | D91: 8 | E91: Clerical | F91: 16200 | G91: 9750 | H91: 92 | J91: No
...

Sheet Pivots
A1: Pivot Summaries (formula-driven)
A2: Built with COUNTIF/AVERAGEIF so they update with the data. To make a native PivotTable: select Clean_Data > Insert > PivotTable.
A4: By Job Category
A5: Job Category | B5: Headcount | C5: Avg Salary | D5: Avg Starting Salary | E5: % of Headcount
A6: Clerical | B6: =COUNTIF(Clean_Data!$E$2:$E$475,A6) -> 363 | C6: =AVERAGEIF(Clean_Data!$E$2:$E$475,A6,Clean_Data!$F$2:$F$475) -> 27838.54 | D6: =AVERAGEIF(Clean_Data!$E$2:$E$475,A6,Clean_Data!$G$2:$G$475) -> 14096.047 | E6: =B6/B$9 -> 0.76582278
A7: Custodial | B7: =COUNTIF(Clean_Data!$E$2:$E$475,A7) -> 27 | C7: =AVERAGEIF(Clean_Data!$E$2:$E$475,A7,Clean_Data!$F$2:$F$475) -> 30938.889 | D7: =AVERAGEIF(Clean_Data!$E$2:$E$475,A7,Clean_Data!$G$2:$G$475) -> 15077.778 | E7: =B7/B$9 -> 0.056962025
A8: Manager | B8: =COUNTIF(Clean_Data!$E$2:$E$475,A8) -> 84 | C8: =AVERAGEIF(Clean_Data!$E$2:$E$475,A8,Clean_Data!$F$2:$F$475) -> 63977.798 | D8: =AVERAGEIF(Clean_Data!$E$2:$E$475,A8,Clean_Data!$G$2:$G$475) -> 30257.857 | E8: =B8/B$9 -> 0.17721519
A9: Total | B9: =SUM(B6:B8) -> 474 | C9: =AVERAGE(Clean_Data!$F$2:$F$475) -> 34419.568 | D9: =AVERAGE(Clean_Data!$G$2:$G$475) -> 17016.087 | E9: =SUM(E6:E8) -> 1
A12: By Gender
A13: Gender | B13: Headcount | C13: Avg Salary | D13: Avg Starting Salary | E13: % of Headcount
A14: Female | B14: =COUNTIF(Clean_Data!$B$2:$B$475,A14) -> 216 | C14: =AVERAGEIF(Clean_Data!$B$2:$B$475,A14,Clean_Data!$F$2:$F$475) -> 26031.921 | D14: =AVERAGEIF(Clean_Data!$B$2:$B$475,A14,Clean_Data!$G$2:$G$475) -> 13091.968 | E14: =B14/B$16 -> 0.4556962
A15: Male | B15: =COUNTIF(Clean_Data!$B$2:$B$475,A15) -> 258 | C15: =AVERAGEIF(Clean_Data!$B$2:$B$475,A15,Clean_Data!$F$2:$F$475) -> 41441.783 | D15: =AVERAGEIF(Clean_Data!$B$2:$B$475,A15,Clean_Data!$G$2:$G$475) -> 20301.395 | E15: =B15/B$16 -> 0.5443038
A16: Total | B16: =SUM(B14:B15) -> 474 | C16: =AVERAGE(Clean_Data!$F$2:$F$475) -> 34419.568 | D16: =AVERAGE(Clean_Data!$G$2:$G$475) -> 17016.087 | E16: =SUM(E14:E15) -> 1
A19: By Minority Status
A20: Minority | B20: Headcount | C20: Avg Salary | D20: Avg Starting Salary | E20: % of Headcount
A21: No | B21: =COUNTIF(Clean_Data!$J$2:$J$475,A21) -> 370 | C21: =AVERAGEIF(Clean_Data!$J$2:$J$475,A21,Clean_Data!$F$2:$F$475) -> 36023.311 | D21: =AVERAGEIF(Clean_Data!$J$2:$J$475,A21,Clean_Data!$G$2:$G$475) -> 17673.014 | E21: =B21/B$23 -> 0.78059072
A22: Yes | B22: =COUNTIF(Clean_Data!$J$2:$J$475,A22) -> 104 | C22: =AVERAGEIF(Clean_Data!$J$2:$J$475,A22,Clean_Data!$F$2:$F$475) -> 28713.942 | D22: =AVERAGEIF(Clean_Data!$J$2:$J$475,A22,Clean_Data!$G$2:$G$475) -> 14678.942 | E22: =B22/B$23 -> 0.21940928
A23: Total | B23: =SUM(B21:B22) -> 474 | C23: =AVERAGE(Clean_Data!$F$2:$F$475) -> 34419.568 | D23: =AVERAGE(Clean_Data!$G$2:$G$475) -> 17016.087 | E23: =SUM(E21:E22) -> 1
A26: Average Salary: Gender x Job Category
A27: Gender | B27: Clerical | C27: Custodial | D27: Manager
A28: Female | B28: =IFERROR(AVERAGEIFS(Clean_Data!$F$2:$F$475,Clean_Data!$B$2:$B$475,$A28,Clean_Data!$E$2:$E$475,B$27),0) -> 25003.689 | C28: =IFERROR(AVERAGEIFS(Clean_Data!$F$2:$F$475,Clean_Data!$B$2:$B$475,$A28,Clean_Data!$E$2:$E$475,C$27),0) -> 0 | D28: =IFERROR(AVERAGEIFS(Clean_Data!$F$2:$F$475,Clean_Data!$B$2:$B$475,$A28,Clean_Data!$E$2:$E$475,D$27),0) -> 47213.5
A29: Male | B29: =IFERROR(AVERAGEIFS(Clean_Data!$F$2:$F$475,Clean_Data!$B$2:$B$475,$A29,Clean_Data!$E$2:$E$475,B$27),0) -> 31558.153 | C29: =IFERROR(AVERAGEIFS(Clean_Data!$F$2:$F$475,Clean_Data!$B$2:$B$475,$A29,Clean_Data!$E$2:$E$475,C$27),0) -> 30938.889 | D29: =IFERROR(AVERAGEIFS(Clean_Data!$F$2:$F$475,Clean_Data!$B$2:$B$475,$A29,Clean_Data!$E$2:$E$475,D$27),0) -> 66243.243
A30: Note: no female employees in Custodial, so that cell shows $0 (IFERROR guard), not a real average.

Sheet Pivot Table 1

Sheet Pivot Table 2

Sheet Charts
A1: Charts

Sheet Summary
A1: Descriptive Statistics - Employee Data
A2: All figures are live formulas over Clean_Data (rows 2-475). Blank cells are ignored by AVERAGE, MEDIAN, etc.
A4: Statistic | B4: Current Salary | C4: Starting Salary | D4: Months in Job | E4: Prev. Experience (months) | F4: Education (yrs)
A5: Mean (Average) | B5: =AVERAGE(Clean_Data!$F$2:$F$475) -> 34419.568 | C5: =AVERAGE(Clean_Data!$G$2:$G$475) -> 17016.087 | D5: =AVERAGE(Clean_Data!$H$2:$H$475) -> 81.109705 | E5: =AVERAGE(Clean_Data!$I$2:$I$475) -> 100.97333 | F5: =AVERAGE(Clean_Data!$D$2:$D$475) -> 13.491561
A6: Median | B6: =MEDIAN(Clean_Data!$F$2:$F$475) -> 28875 | C6: =MEDIAN(Clean_Data!$G$2:$G$475) -> 15000 | D6: =MEDIAN(Clean_Data!$H$2:$H$475) -> 81 | E6: =MEDIAN(Clean_Data!$I$2:$I$475) -> 59 | F6: =MEDIAN(Clean_Data!$D$2:$D$475) -> 12
A7: Mode | B7: =_xlfn.MODE.SNGL(Clean_Data!$F$2:$F$475) -> 30750 | C7: =_xlfn.MODE.SNGL(Clean_Data!$G$2:$G$475) -> 15000 | D7: =_xlfn.MODE.SNGL(Clean_Data!$H$2:$H$475) -> 93 | E7: =_xlfn.MODE.SNGL(Clean_Data!$I$2:$I$475) -> 5 | F7: =_xlfn.MODE.SNGL(Clean_Data!$D$2:$D$475) -> 12
A8: Min | B8: =MIN(Clean_Data!$F$2:$F$475) -> 15750 | C8: =MIN(Clean_Data!$G$2:$G$475) -> 9000 | D8: =MIN(Clean_Data!$H$2:$H$475) -> 63 | E8: =MIN(Clean_Data!$I$2:$I$475) -> 2 | F8: =MIN(Clean_Data!$D$2:$D$475) -> 8
A9: Max | B9: =MAX(Clean_Data!$F$2:$F$475) -> 135000 | C9: =MAX(Clean_Data!$G$2:$G$475) -> 79980 | D9: =MAX(Clean_Data!$H$2:$H$475) -> 98 | E9: =MAX(Clean_Data!$I$2:$I$475) -> 476 | F9: =MAX(Clean_Data!$D$2:$D$475) -> 21
A10: Standard Deviation | B10: =_xlfn.STDEV.S(Clean_Data!$F$2:$F$475) -> 17075.661 | C10: =_xlfn.STDEV.S(Clean_Data!$G$2:$G$475) -> 7870.6382 | D10: =_xlfn.STDEV.S(Clean_Data!$H$2:$H$475) -> 10.060945 | E10: =_xlfn.STDEV.S(Clean_Data!$I$2:$I$475) -> 104.90744 | F10: =_xlfn.STDEV.S(Clean_Data!$D$2:$D$475) -> 2.8848464
A11: Total Count | B11: =COUNT(Clean_Data!$F$2:$F$475) -> 474 | C11: =COUNT(Clean_Data!$G$2:$G$475) -> 474 | D11: =COUNT(Clean_Data!$H$2:$H$475) -> 474 | E11: =COUNT(Clean_Data!$I$2:$I$475) -> 450 | F11: =COUNT(Clean_Data!$D$2:$D$475) -> 474
A12: Blank Cells (not counted) | B12: =COUNTBLANK(Clean_Data!$F$2:$F$475) -> 0 | C12: =COUNTBLANK(Clean_Data!$G$2:$G$475) -> 0 | D12: =COUNTBLANK(Clean_Data!$H$2:$H$475) -> 0 | E12: =COUNTBLANK(Clean_Data!$I$2:$I$475) -> 24 | F12: =COUNTBLANK(Clean_Data!$D$2:$D$475) -> 0
A15: Data-quality check
A16: Rows in Clean_Data | B16: =COUNTA(Clean_Data!$A$2:$A$475) -> 474
A17: Rows in Raw_Data | B17: =COUNTA(Raw_Data!$A$2:$A$475) -> 474
B18: =B17-B16 -> 0
